Workbook

Sheet Mercancia
A1: id_mercancia | B1: nombre | C1: unidad_peso
A2: 1 | B2: mango | C2: objeto
A3: 2 | B3: manzana | C3: objeto
A4: 3 | B4: naranja | C4: objeto
A5: 4 | B5: arroz | C5: kilo
A6: 5 | B6: habichuela | C6: kilo
A7: 6 | B7: lechuga | C7: objeto
A8: 7 | B8: cebolla | C8: kilo
A9: 8 | B9: ajo | C9: kilo
A10: 9 | B10: platano | C10: objeto
A11: 10 | B11: yautía | C11: kilo

Sheet Tasas_Cambio
A1: id_mercancia_a | B1: cantidad_mercancia_a | C1: id_mercancia_b | D1: cantidad_mercancia_b | E1: ultimo_momento_trueque
A2: 1 | C2: 2
A3: 1 | C3: 3
A4: 1 | B4: =Trueque!D2*Medida_Importancia_Mercancia!B2 -> 4.8 | C4: 4 | D4: =Trueque!J2*Medida_Importancia_Mercancia!E2 -> 7.8 | E4: =Trueque!B2 -> 45220.5
A5: 1 | B5: =Trueque!D2*Medida_Importancia_Mercancia!B2 -> 4.8 | C5: 5 | D5: =Trueque!L2*Medida_Importancia_Mercancia!F2 -> 0.16 | E5: =Trueque!B2 -> 45220.5
A6: 1 | B6: =Trueque!L7*Medida_Importancia_Mercancia!F7 -> 25.8 | C6: 6 | D6: =Trueque!F7*Medida_Importancia_Mercancia!C7 -> 12.3 | E6: =Trueque!B7 -> 45221.542
A7: 1 | B7: =Trueque!L7*Medida_Importancia_Mercancia!F7 -> 25.8 | C7: 7 | D7: =Trueque!D7*Medida_Importancia_Mercancia!B7 -> 13.3 | E7: =Trueque!B7 -> 45221.542
A8: 1 | B8: =Trueque!L6*Medida_Importancia_Mercancia!F6 -> 7.2 | C8: 8 | D8: =Trueque!F6*Medida_Importancia_Mercancia!C6 -> 17 | E8: =Trueque!B6 -> 45221.5
A9: 1 | B9: =Trueque!D6*Medida_Importancia_Mercancia!F6 -> 10.8 | C9: 9 | D9: =Trueque!D6*Medida_Importancia_Mercancia!B6 -> 9 | E9: =Trueque!B6 -> 45221.5
A10: 1 | C10: 10
A11: 2 | B11: =Trueque!D3*Medida_Importancia_Mercancia!B3 -> 4.8 | C11: 3 | D11: =Trueque!J3*Medida_Importancia_Mercancia!E3 -> 15.2 | E11: =Trueque!B3 -> 45220.042
A12: 2 | B12: =Trueque!F2*Medida_Importancia_Mercancia!C2 -> 2.1 | C12: 4 | D12: =Trueque!J2*Medida_Importancia_Mercancia!E2 -> 7.8 | E12: =Trueque!B2 -> 45220.5
A13: 2 | B13: =Trueque!F2*Medida_Importancia_Mercancia!C2 -> 2.1 | C13: 5 | D13: =Trueque!L2*Medida_Importancia_Mercancia!F2 -> 0.16 | E13: =Trueque!B2 -> 45220.5
A14: 2 | C14: 6
A15: 2 | C15: 7
A16: 2 | B16: =Trueque!J6*Medida_Importancia_Mercancia!E6 -> 17.6 | C16: 8 | D16: =Trueque!F6*Medida_Importancia_Mercancia!C6 -> 17 | E16: =Trueque!B3 -> 45220.042
A17: 2 | B17: =Trueque!J6*Medida_Importancia_Mercancia!E6 -> 17.6 | C17: 9 | D17: =Trueque!D6*Medida_Importancia_Mercancia!B6 -> 9 | E17: =Trueque!B6 -> 45221.5
A18: 2 | C18: 10
A19: 3 | B19: =Trueque!H2*Medida_Importancia_Mercancia!D2 -> 0.9 | C19: 4 | D19: =Trueque!J2*Medida_Importancia_Mercancia!E2 -> 7.8 | E19: =Trueque!B2 -> 45220.5
A20: 3 | B20: =Trueque!H2*Medida_Importancia_Mercancia!D2 -> 0.9 | C20: 5 | D20: =Trueque!L2*Medida_Importancia_Mercancia!F2 -> 0.16 | E20: =Trueque!B2 -> 45220.5
A21: 3 | B21: =Trueque!L5*Medida_Importancia_Mercancia!F5 -> 38.7 | C21: 6 | D21: =Trueque!D5*Medida_Importancia_Mercancia!B6 -> 6 | E21: =Trueque!B5 -> 45221.458
A22: 3 | B22: =Trueque!J3*Medida_Importancia_Mercancia!E3 -> 15.2 | C22: 7 | D22: =Trueque!F3*Medida_Importancia_Mercancia!C3 -> 10.5 | E22: =Trueque!B3 -> 45220.042
A23: 3 | C23: 8
A24: 3 | C24: 9
A25: 3 | C25: 10
A26: 4 | B26: =Trueque!J5*Medida_Importancia_Mercancia!E5 -> 10.92 | C26: 5 | D26: =Trueque!F5*Medida_Importancia_Mercancia!C6 -> 11 | E26: =Trueque!B5 -> 45221.458
A27: 4 | B27: =Trueque!J5*Medida_Importancia_Mercancia!E5 -> 10.92 | C27: 6 | D27: =Trueque!D5*Medida_Importancia_Mercancia!B5 -> 1.8 | E27: =Trueque!B5 -> 45221.458
A28: 4 | C28: 7
A29: 4 | C29: 8
A30: 4 | C30: 9
A31: 4 | C31: 10
A32: 5 | B32: =Trueque!J7*Medida_Importancia_Mercancia!E7 -> 13.2 | C32: 6 | D32: =Trueque!F7*Medida_Importancia_Mercancia!C7 -> 12.3 | E32: =Trueque!B7 -> 45221.542
A33: 5 | B33: =Trueque!J7*Medida_Importancia_Mercancia!E7 -> 13.2 | C33: 7 | D33: =Trueque!D7*Medida_Importancia_Mercancia!B7 -> 13.3 | E33: =Trueque!B7 -> 45221.542
A34: 5 | C34: 8
A35: 5 | C35: 9
A36: 5 | C36: 10
A37: 6 | C37: 7
A38: 6 | C38: 8
A39: 6 | C39: 9
A40: 6 | C40: 10
...

Sheet Trueque
A1: id_trueque | B1: momento_trueque | C1: id_mercancia_salida_1 | D1: cantidad_mercancia_salida_1 | E1: id_mercancia_salida_2 | F1: cantidad_mercancia_salida_2 | G1: id_mercancia_salida_3 | H1: cantidad_mercancia_salida_3 | I1: id_mercancia_entrada_1 | J1: cantidad_mercancia_entrada_1 | K1: id_mercancia_entrada_2 | L1: cantidad_mercancia_entrada_2 | M1: id_mercancia_entrada_3 | N1: cantidad_mercancia_entrada_3
A2: 1 | B2: 45220.5 | C2: 1 | D2: 8 | E2: 2 | F2: 7 | G2: 3 | H2: 9 | I2: 4 | J2: 13 | K2: 5 | L2: 0.4
A3: 2 | B3: 45220.042 | C3: 2 | D3: 16 | E3: 7 | F3: 15 | I3: 3 | J3: 19 | K3: 8 | L3: 14
A4: 3 | B4: 45221.375 | C4: 9 | D4: 33 | E4: 10 | F4: 15 | I4: 8 | J4: 11 | K4: 7 | L4: 7
A5: 4 | B5: 45221.458 | C5: 6 | D5: 12 | E5: 5 | F5: 22 | I5: 4 | J5: 78 | K5: 3 | L5: 45
A6: 5 | B6: 45221.5 | C6: 9 | D6: 18 | E6: 8 | F6: 34 | I6: 2 | J6: 44 | K6: 1 | L6: 12
A7: 6 | B7: 45221.542 | C7: 7 | D7: 19 | E7: 6 | F7: 41 | I7: 5 | J7: 33 | K7: 1 | L7: 43

Sheet Medida_Importancia_Mercancia
A1: id_trueque | B1: importancia_mercancia_trueque_salida_01 | C1: importancia_mercancia_trueque_salida_2 | D1: importancia_mercancia_trueque_salida_03 | E1: importancia_mercancia_entrada_1 | F1: importancia_mercancia_entrada_2 | G1: importancia_mercancia_entrada_3
A2: 1 | B2: 0.6 | C2: 0.3 | D2: 0.1 | E2: 0.6 | F2: 0.4
A3: 2 | B3: 0.3 | C3: 0.7 | E3: 0.8 | F3: 0.2
A4: 3 | B4: 0.1 | C4: 0.9 | E4: 0.7 | F4: 0.3
A5: 4 | B5: 0.15 | C5: 0.85 | E5: 0.14 | F5: 0.86
A6: 5 | B6: 0.5 | C6: 0.5 | E6: 0.4 | F6: 0.6
A7: 6 | B7: 0.7 | C7: 0.3 | E7: 0.4 | F7: 0.6

Sheet Mercancia_Truequeada
A1: Id. Mercancias/Id.Mercancias | B1: 1 | C1: 2 | D1: 3 | E1: 4 | F1: 5 | G1: 6 | H1: 7 | I1: 8 | J1: 9 | K1: 10
A2: 1 | C2: FALSE | D2: FALSE | E2: TRUE | F2: TRUE | G2: TRUE | H2: TRUE | I2: TRUE | J2: TRUE | K2: FALSE
A3: 2 | B3: FALSE | D3: TRUE | E3: TRUE | F3: TRUE | G3: FALSE | H3: FALSE | I3: TRUE | J3: TRUE | K3: FALSE
A4: 3 | B4: FALSE | C4: TRUE | E4: TRUE | F4: TRUE | G4: TRUE | H4: TRUE | I4: FALSE | J4: FALSE | K4: FALSE
A5: 4 | B5: TRUE | C5: TRUE | D5: TRUE | F5: TRUE | G5: TRUE | H5: FALSE | I5: FALSE | J5: FALSE | K5: FALSE
A6: 5 | B6: TRUE | C6: TRUE | D6: TRUE | E6: TRUE | G6: TRUE | H6: TRUE | I6: FALSE | J6: FALSE | K6: FALSE
A7: 6 | B7: TRUE | C7: FALSE | D7: TRUE | E7: TRUE | F7: TRUE | H7: FALSE | I7: FALSE | J7: FALSE | K7: FALSE
A8: 7 | B8: TRUE | C8: FALSE | D8: TRUE | E8: FALSE | F8: TRUE | G8: FALSE | I8: TRUE | J8: TRUE | K8: TRUE
A9: 8 | B9: TRUE | C9: TRUE | D9: FALSE | E9: FALSE | F9: FALSE | G9: FALSE | H9: TRUE | J9: TRUE | K9: TRUE
A10: 9 | B10: TRUE | C10: TRUE | D10: FALSE | E10: FALSE | F10: FALSE | G10: FALSE | H10: TRUE | I10: TRUE | K10: FALSE
A11: 10 | B11: FALSE | C11: FALSE | D11: FALSE | E11: FALSE | F11: FALSE | G11: FALSE | H11: TRUE | I11: TRUE | J11: FALSE
